[2025-06-21T04:41:22.664+0000] {taskinstance.py:1956} INFO - Dependencies all met for dep_context=non-requeueable deps ti=<TaskInstance: lifebit_health_analytics_pipeline.extract_health_data scheduled__2025-06-20T00:00:00+00:00 [queued]>
[2025-06-21T04:41:22.678+0000] {taskinstance.py:1956} INFO - Dependencies all met for dep_context=requeueable deps ti=<TaskInstance: lifebit_health_analytics_pipeline.extract_health_data scheduled__2025-06-20T00:00:00+00:00 [queued]>
[2025-06-21T04:41:22.679+0000] {taskinstance.py:2170} INFO - Starting attempt 2 of 2
[2025-06-21T04:41:22.707+0000] {taskinstance.py:2191} INFO - Executing <Task(PythonOperator): extract_health_data> on 2025-06-20 00:00:00+00:00
[2025-06-21T04:41:22.733+0000] {standard_task_runner.py:60} INFO - Started process 489 to run task
[2025-06-21T04:41:22.737+0000] {standard_task_runner.py:87} INFO - Running: ['***', 'tasks', 'run', 'lifebit_health_analytics_pipeline', 'extract_health_data', 'scheduled__2025-06-20T00:00:00+00:00', '--job-id', '3', '--raw', '--subdir', 'DAGS_FOLDER/lifebit_health_analytics_dag.py', '--cfg-path', '/tmp/tmp9ln5mqzf']
[2025-06-21T04:41:22.740+0000] {standard_task_runner.py:88} INFO - Job 3: Subtask extract_health_data
[2025-06-21T04:41:22.822+0000] {task_command.py:423} INFO - Running <TaskInstance: lifebit_health_analytics_pipeline.extract_health_data scheduled__2025-06-20T00:00:00+00:00 [running]> on host a6fed5511c4f
[2025-06-21T04:41:22.912+0000] {taskinstance.py:2480} INFO - Exporting env vars: AIRFLOW_CTX_DAG_OWNER='lifebit-team' AIRFLOW_CTX_DAG_ID='lifebit_health_analytics_pipeline' AIRFLOW_CTX_TASK_ID='extract_health_data' AIRFLOW_CTX_EXECUTION_DATE='2025-06-20T00:00:00+00:00' AIRFLOW_CTX_TRY_NUMBER='2' AIRFLOW_CTX_DAG_RUN_ID='scheduled__2025-06-20T00:00:00+00:00'
[2025-06-21T04:41:22.919+0000] {taskinstance.py:2698} ERROR - Task failed with exception
Traceback (most recent call last):
  File "/home/airflow/.local/lib/python3.11/site-packages/airflow/models/taskinstance.py", line 433, in _execute_task
    result = execute_callable(context=context, **execute_callable_kwargs)
             ^^^^^^^^^^^^^^^^^^^^^^^^^^^^^^^^^^^^^^^^^^^^^^^^^^^^^^^^^^^^
  File "/home/airflow/.local/lib/python3.11/site-packages/airflow/operators/python.py", line 199, in execute
    return_value = self.execute_callable()
                   ^^^^^^^^^^^^^^^^^^^^^^^
  File "/home/airflow/.local/lib/python3.11/site-packages/airflow/operators/python.py", line 216, in execute_callable
    return self.python_callable(*self.op_args, **self.op_kwargs)
           ^^^^^^^^^^^^^^^^^^^^^^^^^^^^^^^^^^^^^^^^^^^^^^^^^^^^^
  File "/opt/airflow/dags/lifebit_health_analytics_dag.py", line 52, in extract_health_data
    import pymysql
ModuleNotFoundError: No module named 'pymysql'
[2025-06-21T04:41:22.940+0000] {taskinstance.py:1138} INFO - Marking task as FAILED. dag_id=lifebit_health_analytics_pipeline, task_id=extract_health_data, execution_date=20250620T000000, start_date=20250621T044122, end_date=20250621T044122
[2025-06-21T04:41:22.957+0000] {standard_task_runner.py:107} ERROR - Failed to execute job 3 for task extract_health_data (No module named 'pymysql'; 489)
[2025-06-21T04:41:22.992+0000] {local_task_job_runner.py:234} INFO - Task exited with return code 1
[2025-06-21T04:41:23.029+0000] {taskinstance.py:3280} INFO - 0 downstream tasks scheduled from follow-on schedule check
